[2025-06-28 14:38:47,688] INFO in __init__: Aplicación Casita Bakery iniciada
[2025-06-28 14:39:03,185] INFO in clientes: [CLIENTES] Listando todos los clientes
[2025-06-28 14:39:03,201] INFO in clientes: [CLIENTES] Encontrados 7 clientes
[2025-06-28 14:39:10,200] INFO in productos: [PRODUCTOS] Listando todos los productos
[2025-06-28 14:39:10,224] INFO in productos: [PRODUCTOS] Encontrados 11 productos
[2025-06-28 14:39:15,712] INFO in pedidos: [PEDIDOS] Listando todos los pedidos
[2025-06-28 14:39:22,820] INFO in pedidos: [PEDIDOS] Listado de pedidos con estado: pendiente
[2025-06-28 14:39:30,232] INFO in pedidos: [PEDIDOS] Listado de pedidos con estado: cancelado
[2025-06-28 14:39:34,497] INFO in pedidos: [PEDIDOS] Listado de pedidos con estado: entregado
[2025-06-28 14:39:38,862] INFO in pedidos: [PEDIDOS] Listado de pedidos con estado: entregado
[2025-06-28 14:39:41,917] INFO in pedidos: [PEDIDOS] Listando todos los pedidos
[2025-06-28 14:39:47,823] INFO in clientes: [CLIENTES] Listando todos los clientes
[2025-06-28 14:39:47,826] INFO in productos: [PRODUCTOS] Listando todos los productos
[2025-06-28 14:39:47,838] INFO in clientes: [CLIENTES] Encontrados 7 clientes
[2025-06-28 14:39:47,878] INFO in productos: [PRODUCTOS] Encontrados 11 productos
[2025-06-28 22:28:06,724] INFO in __init__: Aplicación Casita Bakery iniciada
[2025-06-28 22:28:22,696] INFO in pedidos: [PEDIDOS] Listando todos los pedidos
[2025-06-28 22:28:24,712] INFO in productos: [PRODUCTOS] Listando todos los productos
[2025-06-28 22:28:24,751] INFO in productos: [PRODUCTOS] Encontrados 11 productos
[2025-06-28 22:28:25,857] INFO in clientes: [CLIENTES] Listando todos los clientes
[2025-06-28 22:28:25,887] INFO in clientes: [CLIENTES] Encontrados 7 clientes
[2025-06-28 23:03:00,382] INFO in __init__: Aplicación Casita Bakery iniciada
[2025-06-28 23:03:04,601] ERROR in app: Exception on / [GET]
Traceback (most recent call last):
  File "C:\Users\USUARIO\Desktop\Python\Casita_Bakery\venv\Lib\site-packages\flask\app.py", line 1511, in wsgi_app
    response = self.full_dispatch_request()
  File "C:\Users\USUARIO\Desktop\Python\Casita_Bakery\venv\Lib\site-packages\flask\app.py", line 919, in full_dispatch_request
    rv = self.handle_user_exception(e)
  File "C:\Users\USUARIO\Desktop\Python\Casita_Bakery\venv\Lib\site-packages\flask\app.py", line 917, in full_dispatch_request
    rv = self.dispatch_request()
  File "C:\Users\USUARIO\Desktop\Python\Casita_Bakery\venv\Lib\site-packages\flask\app.py", line 902, in dispatch_request
    return self.ensure_sync(self.view_functions[rule.endpoint])(**view_args)  # type: ignore[no-any-return]
           ~~~~~~~~~~~~~~~~~~~~~~~~~~~~~~~~~~~~~~~~~~~~~~~~~~~~^^^^^^^^^^^^^
  File "C:\Users\USUARIO\Desktop\Python\Casita_Bakery\app\routes\dashboard.py", line 8, in index
    return render_template('index.html')
  File "C:\Users\USUARIO\Desktop\Python\Casita_Bakery\venv\Lib\site-packages\flask\templating.py", line 150, in render_template
    return _render(app, template, context)
  File "C:\Users\USUARIO\Desktop\Python\Casita_Bakery\venv\Lib\site-packages\flask\templating.py", line 131, in _render
    rv = template.render(context)
  File "C:\Users\USUARIO\Desktop\Python\Casita_Bakery\venv\Lib\site-packages\jinja2\environment.py", line 1295, in render
    self.environment.handle_exception()
    ~~~~~~~~~~~~~~~~~~~~~~~~~~~~~~~~~^^
  File "C:\Users\USUARIO\Desktop\Python\Casita_Bakery\venv\Lib\site-packages\jinja2\environment.py", line 942, in handle_exception
    raise rewrite_traceback_stack(source=source)
  File "C:\Users\USUARIO\Desktop\Python\Casita_Bakery\app\templates\index.html", line 28, in top-level template code
    <form method="POST" action="{{ url_for('login.login') }}">
    ^^^^^^^^^^^^^
  File "C:\Users\USUARIO\Desktop\Python\Casita_Bakery\venv\Lib\site-packages\flask\app.py", line 1121, in url_for
    return self.handle_url_build_error(error, endpoint, values)
           ~~~~~~~~~~~~~~~~~~~~~~~~~~~^^^^^^^^^^^^^^^^^^^^^^^^^
  File "C:\Users\USUARIO\Desktop\Python\Casita_Bakery\venv\Lib\site-packages\flask\app.py", line 1110, in url_for
    rv = url_adapter.build(  # type: ignore[union-attr]
        endpoint,
    ...<3 lines>...
        force_external=_external,
    )
  File "C:\Users\USUARIO\Desktop\Python\Casita_Bakery\venv\Lib\site-packages\werkzeug\routing\map.py", line 924, in build
    raise BuildError(endpoint, values, method, self)
werkzeug.routing.exceptions.BuildError: Could not build url for endpoint 'login.login'. Did you mean 'main.index' instead?
[2025-06-28 23:03:52,108] INFO in __init__: Aplicación Casita Bakery iniciada
[2025-06-28 23:03:52,898] ERROR in app: Exception on / [GET]
Traceback (most recent call last):
  File "C:\Users\USUARIO\Desktop\Python\Casita_Bakery\venv\Lib\site-packages\flask\app.py", line 1511, in wsgi_app
    response = self.full_dispatch_request()
  File "C:\Users\USUARIO\Desktop\Python\Casita_Bakery\venv\Lib\site-packages\flask\app.py", line 919, in full_dispatch_request
    rv = self.handle_user_exception(e)
  File "C:\Users\USUARIO\Desktop\Python\Casita_Bakery\venv\Lib\site-packages\flask\app.py", line 917, in full_dispatch_request
    rv = self.dispatch_request()
  File "C:\Users\USUARIO\Desktop\Python\Casita_Bakery\venv\Lib\site-packages\flask\app.py", line 902, in dispatch_request
    return self.ensure_sync(self.view_functions[rule.endpoint])(**view_args)  # type: ignore[no-any-return]
           ~~~~~~~~~~~~~~~~~~~~~~~~~~~~~~~~~~~~~~~~~~~~~~~~~~~~^^^^^^^^^^^^^
  File "C:\Users\USUARIO\Desktop\Python\Casita_Bakery\app\routes\dashboard.py", line 8, in index
    return render_template('index.html')
  File "C:\Users\USUARIO\Desktop\Python\Casita_Bakery\venv\Lib\site-packages\flask\templating.py", line 150, in render_template
    return _render(app, template, context)
  File "C:\Users\USUARIO\Desktop\Python\Casita_Bakery\venv\Lib\site-packages\flask\templating.py", line 131, in _render
    rv = template.render(context)
  File "C:\Users\USUARIO\Desktop\Python\Casita_Bakery\venv\Lib\site-packages\jinja2\environment.py", line 1295, in render
    self.environment.handle_exception()
    ~~~~~~~~~~~~~~~~~~~~~~~~~~~~~~~~~^^
  File "C:\Users\USUARIO\Desktop\Python\Casita_Bakery\venv\Lib\site-packages\jinja2\environment.py", line 942, in handle_exception
    raise rewrite_traceback_stack(source=source)
  File "C:\Users\USUARIO\Desktop\Python\Casita_Bakery\app\templates\index.html", line 28, in top-level template code
    <form method="POST" action="{{ url_for('login.login') }}">
    ^^^^^^^^^^^^^
  File "C:\Users\USUARIO\Desktop\Python\Casita_Bakery\venv\Lib\site-packages\flask\app.py", line 1121, in url_for
    return self.handle_url_build_error(error, endpoint, values)
           ~~~~~~~~~~~~~~~~~~~~~~~~~~~^^^^^^^^^^^^^^^^^^^^^^^^^
  File "C:\Users\USUARIO\Desktop\Python\Casita_Bakery\venv\Lib\site-packages\flask\app.py", line 1110, in url_for
    rv = url_adapter.build(  # type: ignore[union-attr]
        endpoint,
    ...<3 lines>...
        force_external=_external,
    )
  File "C:\Users\USUARIO\Desktop\Python\Casita_Bakery\venv\Lib\site-packages\werkzeug\routing\map.py", line 924, in build
    raise BuildError(endpoint, values, method, self)
werkzeug.routing.exceptions.BuildError: Could not build url for endpoint 'login.login'. Did you mean 'main.index' instead?
[2025-06-28 23:04:39,854] INFO in __init__: Aplicación Casita Bakery iniciada
[2025-06-28 23:04:40,358] ERROR in app: Exception on / [GET]
Traceback (most recent call last):
  File "C:\Users\USUARIO\Desktop\Python\Casita_Bakery\venv\Lib\site-packages\flask\app.py", line 1511, in wsgi_app
    response = self.full_dispatch_request()
  File "C:\Users\USUARIO\Desktop\Python\Casita_Bakery\venv\Lib\site-packages\flask\app.py", line 919, in full_dispatch_request
    rv = self.handle_user_exception(e)
  File "C:\Users\USUARIO\Desktop\Python\Casita_Bakery\venv\Lib\site-packages\flask\app.py", line 917, in full_dispatch_request
    rv = self.dispatch_request()
  File "C:\Users\USUARIO\Desktop\Python\Casita_Bakery\venv\Lib\site-packages\flask\app.py", line 902, in dispatch_request
    return self.ensure_sync(self.view_functions[rule.endpoint])(**view_args)  # type: ignore[no-any-return]
           ~~~~~~~~~~~~~~~~~~~~~~~~~~~~~~~~~~~~~~~~~~~~~~~~~~~~^^^^^^^^^^^^^
  File "C:\Users\USUARIO\Desktop\Python\Casita_Bakery\app\routes\dashboard.py", line 8, in index
    return render_template('index.html')
  File "C:\Users\USUARIO\Desktop\Python\Casita_Bakery\venv\Lib\site-packages\flask\templating.py", line 150, in render_template
    return _render(app, template, context)
  File "C:\Users\USUARIO\Desktop\Python\Casita_Bakery\venv\Lib\site-packages\flask\templating.py", line 131, in _render
    rv = template.render(context)
  File "C:\Users\USUARIO\Desktop\Python\Casita_Bakery\venv\Lib\site-packages\jinja2\environment.py", line 1295, in render
    self.environment.handle_exception()
    ~~~~~~~~~~~~~~~~~~~~~~~~~~~~~~~~~^^
  File "C:\Users\USUARIO\Desktop\Python\Casita_Bakery\venv\Lib\site-packages\jinja2\environment.py", line 942, in handle_exception
    raise rewrite_traceback_stack(source=source)
  File "C:\Users\USUARIO\Desktop\Python\Casita_Bakery\app\templates\index.html", line 28, in top-level template code
    <form method="POST" action="{{ url_for('login.login') }}">
    ^^^^^^^^^^^^^
  File "C:\Users\USUARIO\Desktop\Python\Casita_Bakery\venv\Lib\site-packages\flask\app.py", line 1121, in url_for
    return self.handle_url_build_error(error, endpoint, values)
           ~~~~~~~~~~~~~~~~~~~~~~~~~~~^^^^^^^^^^^^^^^^^^^^^^^^^
  File "C:\Users\USUARIO\Desktop\Python\Casita_Bakery\venv\Lib\site-packages\flask\app.py", line 1110, in url_for
    rv = url_adapter.build(  # type: ignore[union-attr]
        endpoint,
    ...<3 lines>...
        force_external=_external,
    )
  File "C:\Users\USUARIO\Desktop\Python\Casita_Bakery\venv\Lib\site-packages\werkzeug\routing\map.py", line 924, in build
    raise BuildError(endpoint, values, method, self)
werkzeug.routing.exceptions.BuildError: Could not build url for endpoint 'login.login'. Did you mean 'main.index' instead?
[2025-06-28 23:04:59,241] INFO in __init__: Aplicación Casita Bakery iniciada
[2025-06-28 23:05:54,843] INFO in __init__: Aplicación Casita Bakery iniciada
[2025-06-28 23:09:16,549] INFO in __init__: Aplicación Casita Bakery iniciada
[2025-06-28 23:11:30,769] INFO in __init__: Aplicación Casita Bakery iniciada
[2025-06-28 23:11:33,642] ERROR in app: Exception on / [GET]
Traceback (most recent call last):
  File "C:\Users\USUARIO\Desktop\Python\Casita_Bakery\venv\Lib\site-packages\flask\app.py", line 1511, in wsgi_app
    response = self.full_dispatch_request()
  File "C:\Users\USUARIO\Desktop\Python\Casita_Bakery\venv\Lib\site-packages\flask\app.py", line 919, in full_dispatch_request
    rv = self.handle_user_exception(e)
  File "C:\Users\USUARIO\Desktop\Python\Casita_Bakery\venv\Lib\site-packages\flask\app.py", line 917, in full_dispatch_request
    rv = self.dispatch_request()
  File "C:\Users\USUARIO\Desktop\Python\Casita_Bakery\venv\Lib\site-packages\flask\app.py", line 902, in dispatch_request
    return self.ensure_sync(self.view_functions[rule.endpoint])(**view_args)  # type: ignore[no-any-return]
           ~~~~~~~~~~~~~~~~~~~~~~~~~~~~~~~~~~~~~~~~~~~~~~~~~~~~^^^^^^^^^^^^^
  File "C:\Users\USUARIO\Desktop\Python\Casita_Bakery\app\routes\main.py", line 23, in login
    return render_template('index.html')
  File "C:\Users\USUARIO\Desktop\Python\Casita_Bakery\venv\Lib\site-packages\flask\templating.py", line 150, in render_template
    return _render(app, template, context)
  File "C:\Users\USUARIO\Desktop\Python\Casita_Bakery\venv\Lib\site-packages\flask\templating.py", line 131, in _render
    rv = template.render(context)
  File "C:\Users\USUARIO\Desktop\Python\Casita_Bakery\venv\Lib\site-packages\jinja2\environment.py", line 1295, in render
    self.environment.handle_exception()
    ~~~~~~~~~~~~~~~~~~~~~~~~~~~~~~~~~^^
  File "C:\Users\USUARIO\Desktop\Python\Casita_Bakery\venv\Lib\site-packages\jinja2\environment.py", line 942, in handle_exception
    raise rewrite_traceback_stack(source=source)
  File "C:\Users\USUARIO\Desktop\Python\Casita_Bakery\app\templates\index.html", line 28, in top-level template code
    <form method="POST" action="{{ url_for('login.login') }}">
    ^^^^^^^^^^^^^
  File "C:\Users\USUARIO\Desktop\Python\Casita_Bakery\venv\Lib\site-packages\flask\app.py", line 1121, in url_for
    return self.handle_url_build_error(error, endpoint, values)
           ~~~~~~~~~~~~~~~~~~~~~~~~~~~^^^^^^^^^^^^^^^^^^^^^^^^^
  File "C:\Users\USUARIO\Desktop\Python\Casita_Bakery\venv\Lib\site-packages\flask\app.py", line 1110, in url_for
    rv = url_adapter.build(  # type: ignore[union-attr]
        endpoint,
    ...<3 lines>...
        force_external=_external,
    )
  File "C:\Users\USUARIO\Desktop\Python\Casita_Bakery\venv\Lib\site-packages\werkzeug\routing\map.py", line 924, in build
    raise BuildError(endpoint, values, method, self)
werkzeug.routing.exceptions.BuildError: Could not build url for endpoint 'login.login'. Did you mean 'main.login' instead?
[2025-06-28 23:12:24,266] INFO in __init__: Aplicación Casita Bakery iniciada
[2025-06-28 23:13:48,287] INFO in clientes: [CLIENTES] Listando todos los clientes
[2025-06-28 23:13:48,398] INFO in clientes: [CLIENTES] Encontrados 7 clientes
[2025-06-28 23:14:56,600] INFO in __init__: Aplicación Casita Bakery iniciada
[2025-06-28 23:15:17,769] INFO in __init__: Aplicación Casita Bakery iniciada
[2025-06-28 23:15:35,283] INFO in __init__: Aplicación Casita Bakery iniciada
[2025-06-28 23:16:26,689] INFO in __init__: Aplicación Casita Bakery iniciada
[2025-06-28 23:19:36,002] INFO in __init__: Aplicación Casita Bakery iniciada
[2025-06-28 23:20:08,972] INFO in __init__: Aplicación Casita Bakery iniciada
[2025-06-28 23:26:18,451] INFO in __init__: Aplicación Casita Bakery iniciada
[2025-06-28 23:37:38,800] INFO in __init__: Aplicación Casita Bakery iniciada
[2025-06-28 23:38:33,313] INFO in __init__: Aplicación Casita Bakery iniciada
[2025-06-28 23:39:58,785] INFO in __init__: Aplicación Casita Bakery iniciada
[2025-06-28 23:40:24,172] INFO in pedidos: [PEDIDOS] Listando todos los pedidos
[2025-06-28 23:45:11,587] INFO in __init__: Aplicación Casita Bakery iniciada
[2025-06-29 18:10:27,707] INFO in __init__: Aplicación Casita Bakery iniciada
[2025-06-29 18:14:41,032] INFO in __init__: Aplicación Casita Bakery iniciada
[2025-06-29 21:11:58,137] INFO in __init__: Aplicación Casita Bakery iniciada
[2025-06-29 21:12:51,838] ERROR in app: Exception on / [POST]
Traceback (most recent call last):
  File "C:\Users\USUARIO\Desktop\Python\Casita_Bakery\venv\Lib\site-packages\flask\app.py", line 1511, in wsgi_app
    response = self.full_dispatch_request()
  File "C:\Users\USUARIO\Desktop\Python\Casita_Bakery\venv\Lib\site-packages\flask\app.py", line 919, in full_dispatch_request
    rv = self.handle_user_exception(e)
  File "C:\Users\USUARIO\Desktop\Python\Casita_Bakery\venv\Lib\site-packages\flask\app.py", line 917, in full_dispatch_request
    rv = self.dispatch_request()
  File "C:\Users\USUARIO\Desktop\Python\Casita_Bakery\venv\Lib\site-packages\flask\app.py", line 902, in dispatch_request
    return self.ensure_sync(self.view_functions[rule.endpoint])(**view_args)  # type: ignore[no-any-return]
           ~~~~~~~~~~~~~~~~~~~~~~~~~~~~~~~~~~~~~~~~~~~~~~~~~~~~^^^^^^^^^^^^^
  File "C:\Users\USUARIO\Desktop\Python\Casita_Bakery\app\routes\main.py", line 16, in login
    login_user(user)  # <-- Flask-Login maneja la sesión
    ~~~~~~~~~~^^^^^^
  File "C:\Users\USUARIO\Desktop\Python\Casita_Bakery\venv\Lib\site-packages\flask_login\utils.py", line 180, in login_user
    if not force and not user.is_active:
                         ^^^^^^^^^^^^^^
AttributeError: 'Usuario' object has no attribute 'is_active'
[2025-06-29 21:14:35,072] INFO in __init__: Aplicación Casita Bakery iniciada
[2025-06-29 21:14:36,458] ERROR in app: Exception on / [POST]
Traceback (most recent call last):
  File "C:\Users\USUARIO\Desktop\Python\Casita_Bakery\venv\Lib\site-packages\flask\app.py", line 1511, in wsgi_app
    response = self.full_dispatch_request()
  File "C:\Users\USUARIO\Desktop\Python\Casita_Bakery\venv\Lib\site-packages\flask\app.py", line 919, in full_dispatch_request
    rv = self.handle_user_exception(e)
  File "C:\Users\USUARIO\Desktop\Python\Casita_Bakery\venv\Lib\site-packages\flask\app.py", line 917, in full_dispatch_request
    rv = self.dispatch_request()
  File "C:\Users\USUARIO\Desktop\Python\Casita_Bakery\venv\Lib\site-packages\flask\app.py", line 902, in dispatch_request
    return self.ensure_sync(self.view_functions[rule.endpoint])(**view_args)  # type: ignore[no-any-return]
           ~~~~~~~~~~~~~~~~~~~~~~~~~~~~~~~~~~~~~~~~~~~~~~~~~~~~^^^^^^^^^^^^^
  File "C:\Users\USUARIO\Desktop\Python\Casita_Bakery\app\routes\main.py", line 16, in login
    login_user(user)  # <-- Flask-Login maneja la sesión
    ~~~~~~~~~~^^^^^^
  File "C:\Users\USUARIO\Desktop\Python\Casita_Bakery\venv\Lib\site-packages\flask_login\utils.py", line 180, in login_user
    if not force and not user.is_active:
                         ^^^^^^^^^^^^^^
AttributeError: 'Usuario' object has no attribute 'is_active'
[2025-06-29 21:14:44,650] ERROR in app: Exception on / [POST]
Traceback (most recent call last):
  File "C:\Users\USUARIO\Desktop\Python\Casita_Bakery\venv\Lib\site-packages\flask\app.py", line 1511, in wsgi_app
    response = self.full_dispatch_request()
  File "C:\Users\USUARIO\Desktop\Python\Casita_Bakery\venv\Lib\site-packages\flask\app.py", line 919, in full_dispatch_request
    rv = self.handle_user_exception(e)
  File "C:\Users\USUARIO\Desktop\Python\Casita_Bakery\venv\Lib\site-packages\flask\app.py", line 917, in full_dispatch_request
    rv = self.dispatch_request()
  File "C:\Users\USUARIO\Desktop\Python\Casita_Bakery\venv\Lib\site-packages\flask\app.py", line 902, in dispatch_request
    return self.ensure_sync(self.view_functions[rule.endpoint])(**view_args)  # type: ignore[no-any-return]
           ~~~~~~~~~~~~~~~~~~~~~~~~~~~~~~~~~~~~~~~~~~~~~~~~~~~~^^^^^^^^^^^^^
  File "C:\Users\USUARIO\Desktop\Python\Casita_Bakery\app\routes\main.py", line 16, in login
    login_user(user)  # <-- Flask-Login maneja la sesión
    ~~~~~~~~~~^^^^^^
  File "C:\Users\USUARIO\Desktop\Python\Casita_Bakery\venv\Lib\site-packages\flask_login\utils.py", line 180, in login_user
    if not force and not user.is_active:
                         ^^^^^^^^^^^^^^
AttributeError: 'Usuario' object has no attribute 'is_active'
[2025-06-29 21:15:23,915] INFO in __init__: Aplicación Casita Bakery iniciada
[2025-06-29 21:15:28,719] ERROR in app: Exception on / [POST]
Traceback (most recent call last):
  File "C:\Users\USUARIO\Desktop\Python\Casita_Bakery\venv\Lib\site-packages\flask\app.py", line 1511, in wsgi_app
    response = self.full_dispatch_request()
  File "C:\Users\USUARIO\Desktop\Python\Casita_Bakery\venv\Lib\site-packages\flask\app.py", line 919, in full_dispatch_request
    rv = self.handle_user_exception(e)
  File "C:\Users\USUARIO\Desktop\Python\Casita_Bakery\venv\Lib\site-packages\flask\app.py", line 917, in full_dispatch_request
    rv = self.dispatch_request()
  File "C:\Users\USUARIO\Desktop\Python\Casita_Bakery\venv\Lib\site-packages\flask\app.py", line 902, in dispatch_request
    return self.ensure_sync(self.view_functions[rule.endpoint])(**view_args)  # type: ignore[no-any-return]
           ~~~~~~~~~~~~~~~~~~~~~~~~~~~~~~~~~~~~~~~~~~~~~~~~~~~~^^^^^^^^^^^^^
  File "C:\Users\USUARIO\Desktop\Python\Casita_Bakery\app\routes\main.py", line 16, in login
    login_user(user)  # <-- Flask-Login maneja la sesión
    ~~~~~~~~~~^^^^^^
  File "C:\Users\USUARIO\Desktop\Python\Casita_Bakery\venv\Lib\site-packages\flask_login\utils.py", line 180, in login_user
    if not force and not user.is_active:
                         ^^^^^^^^^^^^^^
AttributeError: 'Usuario' object has no attribute 'is_active'
[2025-06-29 21:16:29,961] INFO in __init__: Aplicación Casita Bakery iniciada
[2025-06-29 21:18:22,397] INFO in __init__: Aplicación Casita Bakery iniciada
[2025-06-29 21:19:00,587] INFO in __init__: Aplicación Casita Bakery iniciada
[2025-06-29 21:19:27,845] INFO in __init__: Aplicación Casita Bakery iniciada
[2025-06-29 21:24:26,600] INFO in __init__: Aplicación Casita Bakery iniciada
[2025-06-29 21:25:35,401] INFO in clientes: [CLIENTES] Listando todos los clientes
[2025-06-29 21:25:35,500] INFO in clientes: [CLIENTES] Encontrados 7 clientes
[2025-06-29 21:25:37,168] INFO in productos: [PRODUCTOS] Listando todos los productos
[2025-06-29 21:25:37,248] INFO in productos: [PRODUCTOS] Encontrados 11 productos
[2025-06-29 21:25:42,837] INFO in pedidos: [PEDIDOS] Listando todos los pedidos
[2025-06-29 21:25:51,768] INFO in clientes: [CLIENTES] Listando todos los clientes
[2025-06-29 21:25:51,783] INFO in clientes: [CLIENTES] Encontrados 7 clientes
[2025-06-29 21:25:56,962] INFO in pedidos: [PEDIDOS] Listando todos los pedidos
[2025-06-29 21:43:06,768] INFO in __init__: Aplicación Casita Bakery iniciada
[2025-06-29 21:45:14,138] INFO in __init__: Aplicación Casita Bakery iniciada
[2025-07-07 17:21:17,228] INFO in __init__: Aplicación Casita Bakery iniciada
[2025-07-09 23:37:58,344] INFO in __init__: Aplicación Casita Bakery iniciada
[2025-07-09 23:38:45,274] INFO in __init__: Aplicación Casita Bakery iniciada
[2025-07-12 13:25:57,037] INFO in __init__: Aplicación Casita Bakery iniciada
[2025-07-12 13:26:03,836] ERROR in app: Exception on / [GET]
Traceback (most recent call last):
  File "C:\Users\USUARIO\Desktop\Python\Casita_Bakery\venv\Lib\site-packages\pymysql\connections.py", line 649, in connect
    sock = socket.create_connection(
        (self.host, self.port), self.connect_timeout, **kwargs
    )
  File "C:\Users\USUARIO\AppData\Local\Programs\Python\Python313\Lib\socket.py", line 864, in create_connection
    raise exceptions[0]
  File "C:\Users\USUARIO\AppData\Local\Programs\Python\Python313\Lib\socket.py", line 849, in create_connection
    sock.connect(sa)
    ~~~~~~~~~~~~^^^^
ConnectionRefusedError: [WinError 10061] No connection could be made because the target machine actively refused it

During handling of the above exception, another exception occurred:

Traceback (most recent call last):
  File "C:\Users\USUARIO\Desktop\Python\Casita_Bakery\venv\Lib\site-packages\sqlalchemy\engine\base.py", line 145, in __init__
    self._dbapi_connection = engine.raw_connection()
                             ~~~~~~~~~~~~~~~~~~~~~^^
  File "C:\Users\USUARIO\Desktop\Python\Casita_Bakery\venv\Lib\site-packages\sqlalchemy\engine\base.py", line 3297, in raw_connection
    return self.pool.connect()
           ~~~~~~~~~~~~~~~~~^^
  File "C:\Users\USUARIO\Desktop\Python\Casita_Bakery\venv\Lib\site-packages\sqlalchemy\pool\base.py", line 449, in connect
    return _ConnectionFairy._checkout(self)
           ~~~~~~~~~~~~~~~~~~~~~~~~~~^^^^^^
  File "C:\Users\USUARIO\Desktop\Python\Casita_Bakery\venv\Lib\site-packages\sqlalchemy\pool\base.py", line 1264, in _checkout
    fairy = _ConnectionRecord.checkout(pool)
  File "C:\Users\USUARIO\Desktop\Python\Casita_Bakery\venv\Lib\site-packages\sqlalchemy\pool\base.py", line 713, in checkout
    rec = pool._do_get()
  File "C:\Users\USUARIO\Desktop\Python\Casita_Bakery\venv\Lib\site-packages\sqlalchemy\pool\impl.py", line 179, in _do_get
    with util.safe_reraise():
         ~~~~~~~~~~~~~~~~~^^
  File "C:\Users\USUARIO\Desktop\Python\Casita_Bakery\venv\Lib\site-packages\sqlalchemy\util\langhelpers.py", line 224, in __exit__
    raise exc_value.with_traceback(exc_tb)
  File "C:\Users\USUARIO\Desktop\Python\Casita_Bakery\venv\Lib\site-packages\sqlalchemy\pool\impl.py", line 177, in _do_get
    return self._create_connection()
           ~~~~~~~~~~~~~~~~~~~~~~~^^
  File "C:\Users\USUARIO\Desktop\Python\Casita_Bakery\venv\Lib\site-packages\sqlalchemy\pool\base.py", line 390, in _create_connection
    return _ConnectionRecord(self)
  File "C:\Users\USUARIO\Desktop\Python\Casita_Bakery\venv\Lib\site-packages\sqlalchemy\pool\base.py", line 675, in __init__
    self.__connect()
    ~~~~~~~~~~~~~~^^
  File "C:\Users\USUARIO\Desktop\Python\Casita_Bakery\venv\Lib\site-packages\sqlalchemy\pool\base.py", line 901, in __connect
    with util.safe_reraise():
         ~~~~~~~~~~~~~~~~~^^
  File "C:\Users\USUARIO\Desktop\Python\Casita_Bakery\venv\Lib\site-packages\sqlalchemy\util\langhelpers.py", line 224, in __exit__
    raise exc_value.with_traceback(exc_tb)
  File "C:\Users\USUARIO\Desktop\Python\Casita_Bakery\venv\Lib\site-packages\sqlalchemy\pool\base.py", line 897, in __connect
    self.dbapi_connection = connection = pool._invoke_creator(self)
                                         ~~~~~~~~~~~~~~~~~~~~^^^^^^
  File "C:\Users\USUARIO\Desktop\Python\Casita_Bakery\venv\Lib\site-packages\sqlalchemy\engine\create.py", line 646, in connect
    return dialect.connect(*cargs, **cparams)
           ~~~~~~~~~~~~~~~^^^^^^^^^^^^^^^^^^^
  File "C:\Users\USUARIO\Desktop\Python\Casita_Bakery\venv\Lib\site-packages\sqlalchemy\engine\default.py", line 625, in connect
    return self.loaded_dbapi.connect(*cargs, **cparams)  # type: ignore[no-any-return]  # NOQA: E501
           ~~~~~~~~~~~~~~~~~~~~~~~~~^^^^^^^^^^^^^^^^^^^
  File "C:\Users\USUARIO\Desktop\Python\Casita_Bakery\venv\Lib\site-packages\pymysql\connections.py", line 361, in __init__
    self.connect()
    ~~~~~~~~~~~~^^
  File "C:\Users\USUARIO\Desktop\Python\Casita_Bakery\venv\Lib\site-packages\pymysql\connections.py", line 716, in connect
    raise exc
pymysql.err.OperationalError: (2003, "Can't connect to MySQL server on 'localhost' ([WinError 10061] No connection could be made because the target machine actively refused it)")

The above exception was the direct cause of the following exception:

Traceback (most recent call last):
  File "C:\Users\USUARIO\Desktop\Python\Casita_Bakery\venv\Lib\site-packages\flask\app.py", line 1511, in wsgi_app
    response = self.full_dispatch_request()
  File "C:\Users\USUARIO\Desktop\Python\Casita_Bakery\venv\Lib\site-packages\flask\app.py", line 919, in full_dispatch_request
    rv = self.handle_user_exception(e)
  File "C:\Users\USUARIO\Desktop\Python\Casita_Bakery\venv\Lib\site-packages\flask\app.py", line 917, in full_dispatch_request
    rv = self.dispatch_request()
  File "C:\Users\USUARIO\Desktop\Python\Casita_Bakery\venv\Lib\site-packages\flask\app.py", line 902, in dispatch_request
    return self.ensure_sync(self.view_functions[rule.endpoint])(**view_args)  # type: ignore[no-any-return]
           ~~~~~~~~~~~~~~~~~~~~~~~~~~~~~~~~~~~~~~~~~~~~~~~~~~~~^^^^^^^^^^^^^
  File "C:\Users\USUARIO\Desktop\Python\Casita_Bakery\app\routes\main.py", line 22, in login
    return render_template('index.html')
  File "C:\Users\USUARIO\Desktop\Python\Casita_Bakery\venv\Lib\site-packages\flask\templating.py", line 150, in render_template
    return _render(app, template, context)
  File "C:\Users\USUARIO\Desktop\Python\Casita_Bakery\venv\Lib\site-packages\flask\templating.py", line 127, in _render
    app.update_template_context(context)
    ~~~~~~~~~~~~~~~~~~~~~~~~~~~^^^^^^^^^
  File "C:\Users\USUARIO\Desktop\Python\Casita_Bakery\venv\Lib\site-packages\flask\app.py", line 530, in update_template_context
    context.update(self.ensure_sync(func)())
                   ~~~~~~~~~~~~~~~~~~~~~~^^
  File "C:\Users\USUARIO\Desktop\Python\Casita_Bakery\venv\Lib\site-packages\flask_login\utils.py", line 405, in _user_context_processor
    return dict(current_user=_get_user())
                             ~~~~~~~~~^^
  File "C:\Users\USUARIO\Desktop\Python\Casita_Bakery\venv\Lib\site-packages\flask_login\utils.py", line 370, in _get_user
    current_app.login_manager._load_user()
    ~~~~~~~~~~~~~~~~~~~~~~~~~~~~~~~~~~~~^^
  File "C:\Users\USUARIO\Desktop\Python\Casita_Bakery\venv\Lib\site-packages\flask_login\login_manager.py", line 364, in _load_user
    user = self._user_callback(user_id)
  File "C:\Users\USUARIO\Desktop\Python\Casita_Bakery\app\__init__.py", line 26, in load_user
    return Usuario.query.get(int(user_id))
           ~~~~~~~~~~~~~~~~~^^^^^^^^^^^^^^
  File "<string>", line 2, in get
  File "C:\Users\USUARIO\Desktop\Python\Casita_Bakery\venv\Lib\site-packages\sqlalchemy\util\deprecations.py", line 386, in warned
    return fn(*args, **kwargs)  # type: ignore[no-any-return]
  File "C:\Users\USUARIO\Desktop\Python\Casita_Bakery\venv\Lib\site-packages\sqlalchemy\orm\query.py", line 1126, in get
    return self._get_impl(ident, loading.load_on_pk_identity)
           ~~~~~~~~~~~~~~^^^^^^^^^^^^^^^^^^^^^^^^^^^^^^^^^^^^
  File "C:\Users\USUARIO\Desktop\Python\Casita_Bakery\venv\Lib\site-packages\sqlalchemy\orm\query.py", line 1135, in _get_impl
    return self.session._get_impl(
           ~~~~~~~~~~~~~~~~~~~~~~^
        mapper,
        ^^^^^^^
    ...<6 lines>...
        execution_options=self._execution_options,
        ^^^^^^^^^^^^^^^^^^^^^^^^^^^^^^^^^^^^^^^^^^
    )
    ^
  File "C:\Users\USUARIO\Desktop\Python\Casita_Bakery\venv\Lib\site-packages\sqlalchemy\orm\session.py", line 3873, in _get_impl
    return db_load_fn(
        self,
    ...<5 lines>...
        bind_arguments=bind_arguments,
    )
  File "C:\Users\USUARIO\Desktop\Python\Casita_Bakery\venv\Lib\site-packages\sqlalchemy\orm\loading.py", line 694, in load_on_pk_identity
    session.execute(
    ~~~~~~~~~~~~~~~^
        q,
        ^^
    ...<2 lines>...
        bind_arguments=bind_arguments,
        ^^^^^^^^^^^^^^^^^^^^^^^^^^^^^^
    )
    ^
  File "C:\Users\USUARIO\Desktop\Python\Casita_Bakery\venv\Lib\site-packages\sqlalchemy\orm\session.py", line 2365, in execute
    return self._execute_internal(
           ~~~~~~~~~~~~~~~~~~~~~~^
        statement,
        ^^^^^^^^^^
    ...<4 lines>...
        _add_event=_add_event,
        ^^^^^^^^^^^^^^^^^^^^^^
    )
    ^
  File "C:\Users\USUARIO\Desktop\Python\Casita_Bakery\venv\Lib\site-packages\sqlalchemy\orm\session.py", line 2241, in _execute_internal
    conn = self._connection_for_bind(bind)
  File "C:\Users\USUARIO\Desktop\Python\Casita_Bakery\venv\Lib\site-packages\sqlalchemy\orm\session.py", line 2110, in _connection_for_bind
    return trans._connection_for_bind(engine, execution_options)
           ~~~~~~~~~~~~~~~~~~~~~~~~~~^^^^^^^^^^^^^^^^^^^^^^^^^^^
  File "<string>", line 2, in _connection_for_bind
  File "C:\Users\USUARIO\Desktop\Python\Casita_Bakery\venv\Lib\site-packages\sqlalchemy\orm\state_changes.py", line 139, in _go
    ret_value = fn(self, *arg, **kw)
  File "C:\Users\USUARIO\Desktop\Python\Casita_Bakery\venv\Lib\site-packages\sqlalchemy\orm\session.py", line 1189, in _connection_for_bind
    conn = bind.connect()
  File "C:\Users\USUARIO\Desktop\Python\Casita_Bakery\venv\Lib\site-packages\sqlalchemy\engine\base.py", line 3273, in connect
    return self._connection_cls(self)
           ~~~~~~~~~~~~~~~~~~~~^^^^^^
  File "C:\Users\USUARIO\Desktop\Python\Casita_Bakery\venv\Lib\site-packages\sqlalchemy\engine\base.py", line 147, in __init__
    Connection._handle_dbapi_exception_noconnection(
    ~~~~~~~~~~~~~~~~~~~~~~~~~~~~~~~~~~~~~~~~~~~~~~~^
        err, dialect, engine
        ^^^^^^^^^^^^^^^^^^^^
    )
    ^
  File "C:\Users\USUARIO\Desktop\Python\Casita_Bakery\venv\Lib\site-packages\sqlalchemy\engine\base.py", line 2436, in _handle_dbapi_exception_noconnection
    raise sqlalchemy_exception.with_traceback(exc_info[2]) from e
  File "C:\Users\USUARIO\Desktop\Python\Casita_Bakery\venv\Lib\site-packages\sqlalchemy\engine\base.py", line 145, in __init__
    self._dbapi_connection = engine.raw_connection()
                             ~~~~~~~~~~~~~~~~~~~~~^^
  File "C:\Users\USUARIO\Desktop\Python\Casita_Bakery\venv\Lib\site-packages\sqlalchemy\engine\base.py", line 3297, in raw_connection
    return self.pool.connect()
           ~~~~~~~~~~~~~~~~~^^
  File "C:\Users\USUARIO\Desktop\Python\Casita_Bakery\venv\Lib\site-packages\sqlalchemy\pool\base.py", line 449, in connect
    return _ConnectionFairy._checkout(self)
           ~~~~~~~~~~~~~~~~~~~~~~~~~~^^^^^^
  File "C:\Users\USUARIO\Desktop\Python\Casita_Bakery\venv\Lib\site-packages\sqlalchemy\pool\base.py", line 1264, in _checkout
    fairy = _ConnectionRecord.checkout(pool)
  File "C:\Users\USUARIO\Desktop\Python\Casita_Bakery\venv\Lib\site-packages\sqlalchemy\pool\base.py", line 713, in checkout
    rec = pool._do_get()
  File "C:\Users\USUARIO\Desktop\Python\Casita_Bakery\venv\Lib\site-packages\sqlalchemy\pool\impl.py", line 179, in _do_get
    with util.safe_reraise():
         ~~~~~~~~~~~~~~~~~^^
  File "C:\Users\USUARIO\Desktop\Python\Casita_Bakery\venv\Lib\site-packages\sqlalchemy\util\langhelpers.py", line 224, in __exit__
    raise exc_value.with_traceback(exc_tb)
  File "C:\Users\USUARIO\Desktop\Python\Casita_Bakery\venv\Lib\site-packages\sqlalchemy\pool\impl.py", line 177, in _do_get
    return self._create_connection()
           ~~~~~~~~~~~~~~~~~~~~~~~^^
  File "C:\Users\USUARIO\Desktop\Python\Casita_Bakery\venv\Lib\site-packages\sqlalchemy\pool\base.py", line 390, in _create_connection
    return _ConnectionRecord(self)
  File "C:\Users\USUARIO\Desktop\Python\Casita_Bakery\venv\Lib\site-packages\sqlalchemy\pool\base.py", line 675, in __init__
    self.__connect()
    ~~~~~~~~~~~~~~^^
  File "C:\Users\USUARIO\Desktop\Python\Casita_Bakery\venv\Lib\site-packages\sqlalchemy\pool\base.py", line 901, in __connect
    with util.safe_reraise():
         ~~~~~~~~~~~~~~~~~^^
  File "C:\Users\USUARIO\Desktop\Python\Casita_Bakery\venv\Lib\site-packages\sqlalchemy\util\langhelpers.py", line 224, in __exit__
    raise exc_value.with_traceback(exc_tb)
  File "C:\Users\USUARIO\Desktop\Python\Casita_Bakery\venv\Lib\site-packages\sqlalchemy\pool\base.py", line 897, in __connect
    self.dbapi_connection = connection = pool._invoke_creator(self)
                                         ~~~~~~~~~~~~~~~~~~~~^^^^^^
  File "C:\Users\USUARIO\Desktop\Python\Casita_Bakery\venv\Lib\site-packages\sqlalchemy\engine\create.py", line 646, in connect
    return dialect.connect(*cargs, **cparams)
           ~~~~~~~~~~~~~~~^^^^^^^^^^^^^^^^^^^
  File "C:\Users\USUARIO\Desktop\Python\Casita_Bakery\venv\Lib\site-packages\sqlalchemy\engine\default.py", line 625, in connect
    return self.loaded_dbapi.connect(*cargs, **cparams)  # type: ignore[no-any-return]  # NOQA: E501
           ~~~~~~~~~~~~~~~~~~~~~~~~~^^^^^^^^^^^^^^^^^^^
  File "C:\Users\USUARIO\Desktop\Python\Casita_Bakery\venv\Lib\site-packages\pymysql\connections.py", line 361, in __init__
    self.connect()
    ~~~~~~~~~~~~^^
  File "C:\Users\USUARIO\Desktop\Python\Casita_Bakery\venv\Lib\site-packages\pymysql\connections.py", line 716, in connect
    raise exc
sqlalchemy.exc.OperationalError: (pymysql.err.OperationalError) (2003, "Can't connect to MySQL server on 'localhost' ([WinError 10061] No connection could be made because the target machine actively refused it)")
(Background on this error at: https://sqlalche.me/e/20/e3q8)
[2025-07-12 13:26:12,649] ERROR in app: Exception on /favicon.ico [GET]
Traceback (most recent call last):
  File "C:\Users\USUARIO\Desktop\Python\Casita_Bakery\venv\Lib\site-packages\flask\app.py", line 917, in full_dispatch_request
    rv = self.dispatch_request()
  File "C:\Users\USUARIO\Desktop\Python\Casita_Bakery\venv\Lib\site-packages\flask\app.py", line 891, in dispatch_request
    self.raise_routing_exception(req)
    ~~~~~~~~~~~~~~~~~~~~~~~~~~~~^^^^^
  File "C:\Users\USUARIO\Desktop\Python\Casita_Bakery\venv\Lib\site-packages\flask\app.py", line 500, in raise_routing_exception
    raise request.routing_exception  # type: ignore[misc]
    ^^^^^^^^^^^^^^^^^^^^^^^^^^^^^^^
  File "C:\Users\USUARIO\Desktop\Python\Casita_Bakery\venv\Lib\site-packages\flask\ctx.py", line 362, in match_request
    result = self.url_adapter.match(return_rule=True)  # type: ignore
  File "C:\Users\USUARIO\Desktop\Python\Casita_Bakery\venv\Lib\site-packages\werkzeug\routing\map.py", line 629, in match
    raise NotFound() from None
werkzeug.exceptions.NotFound: 404 Not Found: The requested URL was not found on the server. If you entered the URL manually please check your spelling and try again.

During handling of the above exception, another exception occurred:

Traceback (most recent call last):
  File "C:\Users\USUARIO\Desktop\Python\Casita_Bakery\venv\Lib\site-packages\pymysql\connections.py", line 649, in connect
    sock = socket.create_connection(
        (self.host, self.port), self.connect_timeout, **kwargs
    )
  File "C:\Users\USUARIO\AppData\Local\Programs\Python\Python313\Lib\socket.py", line 864, in create_connection
    raise exceptions[0]
  File "C:\Users\USUARIO\AppData\Local\Programs\Python\Python313\Lib\socket.py", line 849, in create_connection
    sock.connect(sa)
    ~~~~~~~~~~~~^^^^
ConnectionRefusedError: [WinError 10061] No connection could be made because the target machine actively refused it

During handling of the above exception, another exception occurred:

Traceback (most recent call last):
  File "C:\Users\USUARIO\Desktop\Python\Casita_Bakery\venv\Lib\site-packages\sqlalchemy\engine\base.py", line 145, in __init__
    self._dbapi_connection = engine.raw_connection()
                             ~~~~~~~~~~~~~~~~~~~~~^^
  File "C:\Users\USUARIO\Desktop\Python\Casita_Bakery\venv\Lib\site-packages\sqlalchemy\engine\base.py", line 3297, in raw_connection
    return self.pool.connect()
           ~~~~~~~~~~~~~~~~~^^
  File "C:\Users\USUARIO\Desktop\Python\Casita_Bakery\venv\Lib\site-packages\sqlalchemy\pool\base.py", line 449, in connect
    return _ConnectionFairy._checkout(self)
           ~~~~~~~~~~~~~~~~~~~~~~~~~~^^^^^^
  File "C:\Users\USUARIO\Desktop\Python\Casita_Bakery\venv\Lib\site-packages\sqlalchemy\pool\base.py", line 1264, in _checkout
    fairy = _ConnectionRecord.checkout(pool)
  File "C:\Users\USUARIO\Desktop\Python\Casita_Bakery\venv\Lib\site-packages\sqlalchemy\pool\base.py", line 713, in checkout
    rec = pool._do_get()
  File "C:\Users\USUARIO\Desktop\Python\Casita_Bakery\venv\Lib\site-packages\sqlalchemy\pool\impl.py", line 179, in _do_get
    with util.safe_reraise():
         ~~~~~~~~~~~~~~~~~^^
  File "C:\Users\USUARIO\Desktop\Python\Casita_Bakery\venv\Lib\site-packages\sqlalchemy\util\langhelpers.py", line 224, in __exit__
    raise exc_value.with_traceback(exc_tb)
  File "C:\Users\USUARIO\Desktop\Python\Casita_Bakery\venv\Lib\site-packages\sqlalchemy\pool\impl.py", line 177, in _do_get
    return self._create_connection()
           ~~~~~~~~~~~~~~~~~~~~~~~^^
  File "C:\Users\USUARIO\Desktop\Python\Casita_Bakery\venv\Lib\site-packages\sqlalchemy\pool\base.py", line 390, in _create_connection
    return _ConnectionRecord(self)
  File "C:\Users\USUARIO\Desktop\Python\Casita_Bakery\venv\Lib\site-packages\sqlalchemy\pool\base.py", line 675, in __init__
    self.__connect()
    ~~~~~~~~~~~~~~^^
  File "C:\Users\USUARIO\Desktop\Python\Casita_Bakery\venv\Lib\site-packages\sqlalchemy\pool\base.py", line 901, in __connect
    with util.safe_reraise():
         ~~~~~~~~~~~~~~~~~^^
  File "C:\Users\USUARIO\Desktop\Python\Casita_Bakery\venv\Lib\site-packages\sqlalchemy\util\langhelpers.py", line 224, in __exit__
    raise exc_value.with_traceback(exc_tb)
  File "C:\Users\USUARIO\Desktop\Python\Casita_Bakery\venv\Lib\site-packages\sqlalchemy\pool\base.py", line 897, in __connect
    self.dbapi_connection = connection = pool._invoke_creator(self)
                                         ~~~~~~~~~~~~~~~~~~~~^^^^^^
  File "C:\Users\USUARIO\Desktop\Python\Casita_Bakery\venv\Lib\site-packages\sqlalchemy\engine\create.py", line 646, in connect
    return dialect.connect(*cargs, **cparams)
           ~~~~~~~~~~~~~~~^^^^^^^^^^^^^^^^^^^
  File "C:\Users\USUARIO\Desktop\Python\Casita_Bakery\venv\Lib\site-packages\sqlalchemy\engine\default.py", line 625, in connect
    return self.loaded_dbapi.connect(*cargs, **cparams)  # type: ignore[no-any-return]  # NOQA: E501
           ~~~~~~~~~~~~~~~~~~~~~~~~~^^^^^^^^^^^^^^^^^^^
  File "C:\Users\USUARIO\Desktop\Python\Casita_Bakery\venv\Lib\site-packages\pymysql\connections.py", line 361, in __init__
    self.connect()
    ~~~~~~~~~~~~^^
  File "C:\Users\USUARIO\Desktop\Python\Casita_Bakery\venv\Lib\site-packages\pymysql\connections.py", line 716, in connect
    raise exc
pymysql.err.OperationalError: (2003, "Can't connect to MySQL server on 'localhost' ([WinError 10061] No connection could be made because the target machine actively refused it)")

The above exception was the direct cause of the following exception:

Traceback (most recent call last):
  File "C:\Users\USUARIO\Desktop\Python\Casita_Bakery\venv\Lib\site-packages\flask\app.py", line 1511, in wsgi_app
    response = self.full_dispatch_request()
  File "C:\Users\USUARIO\Desktop\Python\Casita_Bakery\venv\Lib\site-packages\flask\app.py", line 919, in full_dispatch_request
    rv = self.handle_user_exception(e)
  File "C:\Users\USUARIO\Desktop\Python\Casita_Bakery\venv\Lib\site-packages\flask\app.py", line 802, in handle_user_exception
    return self.handle_http_exception(e)
           ~~~~~~~~~~~~~~~~~~~~~~~~~~^^^
  File "C:\Users\USUARIO\Desktop\Python\Casita_Bakery\venv\Lib\site-packages\flask\app.py", line 777, in handle_http_exception
    return self.ensure_sync(handler)(e)  # type: ignore[no-any-return]
           ~~~~~~~~~~~~~~~~~~~~~~~~~^^^
  File "C:\Users\USUARIO\Desktop\Python\Casita_Bakery\app\__init__.py", line 66, in pagina_no_encontrada
    return render_template("errors/404.html"), 404
           ~~~~~~~~~~~~~~~^^^^^^^^^^^^^^^^^^^
  File "C:\Users\USUARIO\Desktop\Python\Casita_Bakery\venv\Lib\site-packages\flask\templating.py", line 150, in render_template
    return _render(app, template, context)
  File "C:\Users\USUARIO\Desktop\Python\Casita_Bakery\venv\Lib\site-packages\flask\templating.py", line 127, in _render
    app.update_template_context(context)
    ~~~~~~~~~~~~~~~~~~~~~~~~~~~^^^^^^^^^
  File "C:\Users\USUARIO\Desktop\Python\Casita_Bakery\venv\Lib\site-packages\flask\app.py", line 530, in update_template_context
    context.update(self.ensure_sync(func)())
                   ~~~~~~~~~~~~~~~~~~~~~~^^
  File "C:\Users\USUARIO\Desktop\Python\Casita_Bakery\venv\Lib\site-packages\flask_login\utils.py", line 405, in _user_context_processor
    return dict(current_user=_get_user())
                             ~~~~~~~~~^^
  File "C:\Users\USUARIO\Desktop\Python\Casita_Bakery\venv\Lib\site-packages\flask_login\utils.py", line 370, in _get_user
    current_app.login_manager._load_user()
    ~~~~~~~~~~~~~~~~~~~~~~~~~~~~~~~~~~~~^^
  File "C:\Users\USUARIO\Desktop\Python\Casita_Bakery\venv\Lib\site-packages\flask_login\login_manager.py", line 364, in _load_user
    user = self._user_callback(user_id)
  File "C:\Users\USUARIO\Desktop\Python\Casita_Bakery\app\__init__.py", line 26, in load_user
    return Usuario.query.get(int(user_id))
           ~~~~~~~~~~~~~~~~~^^^^^^^^^^^^^^
  File "<string>", line 2, in get
  File "C:\Users\USUARIO\Desktop\Python\Casita_Bakery\venv\Lib\site-packages\sqlalchemy\util\deprecations.py", line 386, in warned
    return fn(*args, **kwargs)  # type: ignore[no-any-return]
  File "C:\Users\USUARIO\Desktop\Python\Casita_Bakery\venv\Lib\site-packages\sqlalchemy\orm\query.py", line 1126, in get
    return self._get_impl(ident, loading.load_on_pk_identity)
           ~~~~~~~~~~~~~~^^^^^^^^^^^^^^^^^^^^^^^^^^^^^^^^^^^^
  File "C:\Users\USUARIO\Desktop\Python\Casita_Bakery\venv\Lib\site-packages\sqlalchemy\orm\query.py", line 1135, in _get_impl
    return self.session._get_impl(
           ~~~~~~~~~~~~~~~~~~~~~~^
        mapper,
        ^^^^^^^
    ...<6 lines>...
        execution_options=self._execution_options,
        ^^^^^^^^^^^^^^^^^^^^^^^^^^^^^^^^^^^^^^^^^^
    )
    ^
  File "C:\Users\USUARIO\Desktop\Python\Casita_Bakery\venv\Lib\site-packages\sqlalchemy\orm\session.py", line 3873, in _get_impl
    return db_load_fn(
        self,
    ...<5 lines>...
        bind_arguments=bind_arguments,
    )
  File "C:\Users\USUARIO\Desktop\Python\Casita_Bakery\venv\Lib\site-packages\sqlalchemy\orm\loading.py", line 694, in load_on_pk_identity
    session.execute(
    ~~~~~~~~~~~~~~~^
        q,
        ^^
    ...<2 lines>...
        bind_arguments=bind_arguments,
        ^^^^^^^^^^^^^^^^^^^^^^^^^^^^^^
    )
    ^
  File "C:\Users\USUARIO\Desktop\Python\Casita_Bakery\venv\Lib\site-packages\sqlalchemy\orm\session.py", line 2365, in execute
    return self._execute_internal(
           ~~~~~~~~~~~~~~~~~~~~~~^
        statement,
        ^^^^^^^^^^
    ...<4 lines>...
        _add_event=_add_event,
        ^^^^^^^^^^^^^^^^^^^^^^
    )
    ^
  File "C:\Users\USUARIO\Desktop\Python\Casita_Bakery\venv\Lib\site-packages\sqlalchemy\orm\session.py", line 2241, in _execute_internal
    conn = self._connection_for_bind(bind)
  File "C:\Users\USUARIO\Desktop\Python\Casita_Bakery\venv\Lib\site-packages\sqlalchemy\orm\session.py", line 2110, in _connection_for_bind
    return trans._connection_for_bind(engine, execution_options)
           ~~~~~~~~~~~~~~~~~~~~~~~~~~^^^^^^^^^^^^^^^^^^^^^^^^^^^
  File "<string>", line 2, in _connection_for_bind
  File "C:\Users\USUARIO\Desktop\Python\Casita_Bakery\venv\Lib\site-packages\sqlalchemy\orm\state_changes.py", line 139, in _go
    ret_value = fn(self, *arg, **kw)
  File "C:\Users\USUARIO\Desktop\Python\Casita_Bakery\venv\Lib\site-packages\sqlalchemy\orm\session.py", line 1189, in _connection_for_bind
    conn = bind.connect()
  File "C:\Users\USUARIO\Desktop\Python\Casita_Bakery\venv\Lib\site-packages\sqlalchemy\engine\base.py", line 3273, in connect
    return self._connection_cls(self)
           ~~~~~~~~~~~~~~~~~~~~^^^^^^
  File "C:\Users\USUARIO\Desktop\Python\Casita_Bakery\venv\Lib\site-packages\sqlalchemy\engine\base.py", line 147, in __init__
    Connection._handle_dbapi_exception_noconnection(
    ~~~~~~~~~~~~~~~~~~~~~~~~~~~~~~~~~~~~~~~~~~~~~~~^
        err, dialect, engine
        ^^^^^^^^^^^^^^^^^^^^
    )
    ^
  File "C:\Users\USUARIO\Desktop\Python\Casita_Bakery\venv\Lib\site-packages\sqlalchemy\engine\base.py", line 2436, in _handle_dbapi_exception_noconnection
    raise sqlalchemy_exception.with_traceback(exc_info[2]) from e
  File "C:\Users\USUARIO\Desktop\Python\Casita_Bakery\venv\Lib\site-packages\sqlalchemy\engine\base.py", line 145, in __init__
    self._dbapi_connection = engine.raw_connection()
                             ~~~~~~~~~~~~~~~~~~~~~^^
  File "C:\Users\USUARIO\Desktop\Python\Casita_Bakery\venv\Lib\site-packages\sqlalchemy\engine\base.py", line 3297, in raw_connection
    return self.pool.connect()
           ~~~~~~~~~~~~~~~~~^^
  File "C:\Users\USUARIO\Desktop\Python\Casita_Bakery\venv\Lib\site-packages\sqlalchemy\pool\base.py", line 449, in connect
    return _ConnectionFairy._checkout(self)
           ~~~~~~~~~~~~~~~~~~~~~~~~~~^^^^^^
  File "C:\Users\USUARIO\Desktop\Python\Casita_Bakery\venv\Lib\site-packages\sqlalchemy\pool\base.py", line 1264, in _checkout
    fairy = _ConnectionRecord.checkout(pool)
  File "C:\Users\USUARIO\Desktop\Python\Casita_Bakery\venv\Lib\site-packages\sqlalchemy\pool\base.py", line 713, in checkout
    rec = pool._do_get()
  File "C:\Users\USUARIO\Desktop\Python\Casita_Bakery\venv\Lib\site-packages\sqlalchemy\pool\impl.py", line 179, in _do_get
    with util.safe_reraise():
         ~~~~~~~~~~~~~~~~~^^
  File "C:\Users\USUARIO\Desktop\Python\Casita_Bakery\venv\Lib\site-packages\sqlalchemy\util\langhelpers.py", line 224, in __exit__
    raise exc_value.with_traceback(exc_tb)
  File "C:\Users\USUARIO\Desktop\Python\Casita_Bakery\venv\Lib\site-packages\sqlalchemy\pool\impl.py", line 177, in _do_get
    return self._create_connection()
           ~~~~~~~~~~~~~~~~~~~~~~~^^
  File "C:\Users\USUARIO\Desktop\Python\Casita_Bakery\venv\Lib\site-packages\sqlalchemy\pool\base.py", line 390, in _create_connection
    return _ConnectionRecord(self)
  File "C:\Users\USUARIO\Desktop\Python\Casita_Bakery\venv\Lib\site-packages\sqlalchemy\pool\base.py", line 675, in __init__
    self.__connect()
    ~~~~~~~~~~~~~~^^
  File "C:\Users\USUARIO\Desktop\Python\Casita_Bakery\venv\Lib\site-packages\sqlalchemy\pool\base.py", line 901, in __connect
    with util.safe_reraise():
         ~~~~~~~~~~~~~~~~~^^
  File "C:\Users\USUARIO\Desktop\Python\Casita_Bakery\venv\Lib\site-packages\sqlalchemy\util\langhelpers.py", line 224, in __exit__
    raise exc_value.with_traceback(exc_tb)
  File "C:\Users\USUARIO\Desktop\Python\Casita_Bakery\venv\Lib\site-packages\sqlalchemy\pool\base.py", line 897, in __connect
    self.dbapi_connection = connection = pool._invoke_creator(self)
                                         ~~~~~~~~~~~~~~~~~~~~^^^^^^
  File "C:\Users\USUARIO\Desktop\Python\Casita_Bakery\venv\Lib\site-packages\sqlalchemy\engine\create.py", line 646, in connect
    return dialect.connect(*cargs, **cparams)
           ~~~~~~~~~~~~~~~^^^^^^^^^^^^^^^^^^^
  File "C:\Users\USUARIO\Desktop\Python\Casita_Bakery\venv\Lib\site-packages\sqlalchemy\engine\default.py", line 625, in connect
    return self.loaded_dbapi.connect(*cargs, **cparams)  # type: ignore[no-any-return]  # NOQA: E501
           ~~~~~~~~~~~~~~~~~~~~~~~~~^^^^^^^^^^^^^^^^^^^
  File "C:\Users\USUARIO\Desktop\Python\Casita_Bakery\venv\Lib\site-packages\pymysql\connections.py", line 361, in __init__
    self.connect()
    ~~~~~~~~~~~~^^
  File "C:\Users\USUARIO\Desktop\Python\Casita_Bakery\venv\Lib\site-packages\pymysql\connections.py", line 716, in connect
    raise exc
sqlalchemy.exc.OperationalError: (pymysql.err.OperationalError) (2003, "Can't connect to MySQL server on 'localhost' ([WinError 10061] No connection could be made because the target machine actively refused it)")
(Background on this error at: https://sqlalche.me/e/20/e3q8)
[2025-07-12 13:27:36,160] INFO in __init__: Aplicación Casita Bakery iniciada
[2025-07-12 13:27:56,722] INFO in clientes: [CLIENTES] Listando todos los clientes
[2025-07-12 13:27:56,763] INFO in clientes: [CLIENTES] Encontrados 7 clientes
[2025-07-12 13:28:00,186] INFO in clientes: [CLIENTES] Listando todos los clientes
[2025-07-12 13:28:00,212] INFO in clientes: [CLIENTES] Encontrados 7 clientes
[2025-07-12 13:28:06,281] INFO in clientes: [CLIENTES] Listando todos los clientes
[2025-07-12 13:28:06,296] INFO in clientes: [CLIENTES] Encontrados 7 clientes
[2025-07-12 13:28:11,194] INFO in clientes: [CLIENTES] Visualizando detalles del cliente - ID: 37, Nombre: Luis Medina
[2025-07-12 13:28:18,515] INFO in clientes: [CLIENTES] Listando todos los clientes
[2025-07-12 13:28:18,550] INFO in clientes: [CLIENTES] Encontrados 7 clientes
[2025-07-12 13:28:26,017] INFO in productos: [PRODUCTOS] Listando todos los productos
[2025-07-12 13:28:26,058] INFO in productos: [PRODUCTOS] Encontrados 11 productos
[2025-07-12 13:28:32,450] INFO in productos: [PRODUCTO] Visualizando detalles del Producto - ID: 12, Nombre: Galleta rellena de Dulce de leche
[2025-07-12 13:28:34,099] INFO in productos: [PRODUCTOS] Listando todos los productos
[2025-07-12 13:28:34,126] INFO in productos: [PRODUCTOS] Encontrados 11 productos
[2025-07-12 13:28:37,612] INFO in pedidos: [PEDIDOS] Listando todos los pedidos
[2025-07-12 13:35:14,725] INFO in pedidos: [PEDIDOS] Listando todos los pedidos
[2025-07-12 13:36:28,217] INFO in pedidos: [PEDIDOS] Listando todos los pedidos
[2025-07-12 13:36:31,993] INFO in clientes: [CLIENTES] Listando todos los clientes
[2025-07-12 13:36:32,001] INFO in productos: [PRODUCTOS] Listando todos los productos
[2025-07-12 13:36:32,033] INFO in clientes: [CLIENTES] Encontrados 7 clientes
[2025-07-12 13:36:32,050] INFO in productos: [PRODUCTOS] Encontrados 11 productos
[2025-07-21 22:17:11,702] INFO in __init__: Aplicación Casita Bakery iniciada
[2025-07-21 22:23:11,692] INFO in clientes: [CLIENTES] Listando todos los clientes
[2025-07-21 22:23:11,712] INFO in clientes: [CLIENTES] Encontrados 7 clientes
[2025-07-21 22:23:40,346] INFO in clientes: [CLIENTES] Listando todos los clientes
[2025-07-21 22:23:40,350] INFO in clientes: [CLIENTES] Encontrados 7 clientes
[2025-07-21 22:34:07,120] INFO in clientes: [CLIENTES] Listando todos los clientes
[2025-07-21 22:34:07,135] INFO in clientes: [CLIENTES] Encontrados 7 clientes
[2025-07-21 22:34:26,132] WARNING in clientes: [CLIENTES] Intento de ver detalles de cliente inexistente - ID: 1
[2025-07-21 22:35:45,086] INFO in clientes: [CLIENTES] Iniciando eliminación del cliente ID: 30
[2025-07-21 22:35:45,088] WARNING in clientes: [CLIENTES] Intento de eliminar cliente inexistente - ID: 30
[2025-07-21 22:36:22,360] ERROR in clientes: [CLIENTES] Cliente con ID 30 no encontrado
[2025-07-21 22:36:26,941] ERROR in clientes: [CLIENTES] Cliente con ID 30 no encontrado
[2025-07-21 22:36:34,583] INFO in clientes: [CLIENTES] Iniciando eliminación del cliente ID: 30
[2025-07-21 22:36:34,585] WARNING in clientes: [CLIENTES] Intento de eliminar cliente inexistente - ID: 30
[2025-07-21 22:36:47,886] INFO in clientes: [CLIENTES] Iniciando eliminación del cliente ID: 10
[2025-07-21 22:36:47,975] INFO in clientes: [CLIENTES] Cliente eliminado exitosamente - ID: 10, Nombre: Abdiel Mendoza, Fecha Registro: 2025-06-06 00:11:00
[2025-07-21 22:36:59,320] INFO in clientes: [CLIENTES] Listando todos los clientes
[2025-07-21 22:36:59,323] INFO in clientes: [CLIENTES] Encontrados 6 clientes
[2025-07-21 22:38:29,993] INFO in clientes: [CLIENTES] Listando todos los clientes
[2025-07-21 22:38:29,995] INFO in clientes: [CLIENTES] Encontrados 6 clientes
[2025-07-21 22:39:41,366] INFO in clientes: [CLIENTES] Listando todos los clientes
[2025-07-21 22:39:41,367] INFO in clientes: [CLIENTES] Encontrados 6 clientes
[2025-07-21 22:39:56,135] INFO in clientes: [CLIENTES] Cliente creado: Abdiel Mendoza (ID: 38)
[2025-07-21 22:40:39,771] INFO in clientes: [CLIENTES] Listando todos los clientes
[2025-07-21 22:40:39,773] INFO in clientes: [CLIENTES] Encontrados 7 clientes
[2025-07-21 22:40:44,634] INFO in clientes: [CLIENTES] Listando todos los clientes
[2025-07-21 22:40:44,639] INFO in clientes: [CLIENTES] Encontrados 7 clientes
